[2023-09-14T17:56:05.850+0100] {taskinstance.py:1157} INFO - Dependencies all met for dep_context=non-requeueable deps ti=<TaskInstance: example_of_ecommerce_pipeline.extract_product_data scheduled__2022-03-16T00:00:00+00:00 [queued]>
[2023-09-14T17:56:05.855+0100] {taskinstance.py:1157} INFO - Dependencies all met for dep_context=requeueable deps ti=<TaskInstance: example_of_ecommerce_pipeline.extract_product_data scheduled__2022-03-16T00:00:00+00:00 [queued]>
[2023-09-14T17:56:05.856+0100] {taskinstance.py:1359} INFO - Starting attempt 1 of 1
[2023-09-14T17:56:05.875+0100] {taskinstance.py:1380} INFO - Executing <Task(PythonOperator): extract_product_data> on 2022-03-16 00:00:00+00:00
[2023-09-14T17:56:05.879+0100] {standard_task_runner.py:57} INFO - Started process 37983 to run task
[2023-09-14T17:56:05.883+0100] {standard_task_runner.py:84} INFO - Running: ['airflow', 'tasks', 'run', 'example_of_ecommerce_pipeline', 'extract_product_data', 'scheduled__2022-03-16T00:00:00+00:00', '--job-id', '58', '--raw', '--subdir', 'DAGS_FOLDER/etl_dag.py', '--cfg-path', '/tmp/tmpcly0u70f']
[2023-09-14T17:56:05.883+0100] {standard_task_runner.py:85} INFO - Job 58: Subtask extract_product_data
[2023-09-14T17:56:05.921+0100] {task_command.py:415} INFO - Running <TaskInstance: example_of_ecommerce_pipeline.extract_product_data scheduled__2022-03-16T00:00:00+00:00 [running]> on host ubuntu
[2023-09-14T17:56:05.984+0100] {taskinstance.py:1660} INFO - Exporting env vars: AIRFLOW_CTX_DAG_OWNER='airflow' AIRFLOW_CTX_DAG_ID='example_of_ecommerce_pipeline' AIRFLOW_CTX_TASK_ID='extract_product_data' AIRFLOW_CTX_EXECUTION_DATE='2022-03-16T00:00:00+00:00' AIRFLOW_CTX_TRY_NUMBER='1' AIRFLOW_CTX_DAG_RUN_ID='scheduled__2022-03-16T00:00:00+00:00'
[2023-09-14T17:56:05.987+0100] {taskinstance.py:1935} ERROR - Task failed with exception
Traceback (most recent call last):
  File "/home/joestar/Documents/projects/airflow_etl/airflow_env/lib/python3.8/site-packages/mysql/connector/network.py", line 733, in open_connection
    self.sock.connect(sockaddr)
ConnectionRefusedError: [Errno 111] Connection refused

The above exception was the direct cause of the following exception:

Traceback (most recent call last):
  File "/home/joestar/Documents/projects/airflow_etl/airflow_env/lib/python3.8/site-packages/airflow/operators/python.py", line 192, in execute
    return_value = self.execute_callable()
  File "/home/joestar/Documents/projects/airflow_etl/airflow_env/lib/python3.8/site-packages/airflow/operators/python.py", line 209, in execute_callable
    return self.python_callable(*self.op_args, **self.op_kwargs)
  File "/home/joestar/Documents/projects/airflow_etl/dags/etl_dag.py", line 37, in extract_product_data
    conn = Connect(
  File "/home/joestar/Documents/projects/airflow_etl/airflow_env/lib/python3.8/site-packages/mysql/connector/pooling.py", line 294, in connect
    return MySQLConnection(*args, **kwargs)
  File "/home/joestar/Documents/projects/airflow_etl/airflow_env/lib/python3.8/site-packages/mysql/connector/connection.py", line 169, in __init__
    self.connect(**kwargs)
  File "/home/joestar/Documents/projects/airflow_etl/airflow_env/lib/python3.8/site-packages/mysql/connector/abstracts.py", line 1217, in connect
    self._open_connection()
  File "/home/joestar/Documents/projects/airflow_etl/airflow_env/lib/python3.8/site-packages/mysql/connector/connection.py", line 575, in _open_connection
    self._socket.open_connection()
  File "/home/joestar/Documents/projects/airflow_etl/airflow_env/lib/python3.8/site-packages/mysql/connector/network.py", line 735, in open_connection
    raise InterfaceError(
mysql.connector.errors.InterfaceError: 2003: Can't connect to MySQL server on 'localhost:3306' (111 Connection refused)
[2023-09-14T17:56:05.992+0100] {taskinstance.py:1398} INFO - Marking task as FAILED. dag_id=example_of_ecommerce_pipeline, task_id=extract_product_data, execution_date=20220316T000000, start_date=20230914T165605, end_date=20230914T165605
[2023-09-14T17:56:06.007+0100] {standard_task_runner.py:104} ERROR - Failed to execute job 58 for task extract_product_data (2003: Can't connect to MySQL server on 'localhost:3306' (111 Connection refused); 37983)
[2023-09-14T17:56:06.014+0100] {local_task_job_runner.py:228} INFO - Task exited with return code 1
[2023-09-14T17:56:06.034+0100] {taskinstance.py:2776} INFO - 0 downstream tasks scheduled from follow-on schedule check
